2019-01-06 15:17:11,791 - INFO: Microblog startup [in C:\Users\thanhpd8\Downloads\learning-python\learning-flask\microblog\app\__init__.py:47]
2019-01-06 15:18:06,672 - ERROR: Exception on /edit_profile [POST] [in c:\users\thanhpd8\appdata\local\programs\python\python37-32\lib\site-packages\flask\app.py:1761]
Traceback (most recent call last):
  File "c:\users\thanhpd8\appdata\local\programs\python\python37-32\lib\site-packages\sqlalchemy\engine\base.py", line 1193, in _execute_context
    context)
  File "c:\users\thanhpd8\appdata\local\programs\python\python37-32\lib\site-packages\sqlalchemy\engine\default.py", line 509, in do_execute
    cursor.execute(statement, parameters)
sqlite3.IntegrityError: UNIQUE constraint failed: user.username

The above exception was the direct cause of the following exception:

Traceback (most recent call last):
  File "c:\users\thanhpd8\appdata\local\programs\python\python37-32\lib\site-packages\flask\app.py", line 2292, in wsgi_app
    response = self.full_dispatch_request()
  File "c:\users\thanhpd8\appdata\local\programs\python\python37-32\lib\site-packages\flask\app.py", line 1815, in full_dispatch_request
    rv = self.handle_user_exception(e)
  File "c:\users\thanhpd8\appdata\local\programs\python\python37-32\lib\site-packages\flask\app.py", line 1718, in handle_user_exception
    reraise(exc_type, exc_value, tb)
  File "c:\users\thanhpd8\appdata\local\programs\python\python37-32\lib\site-packages\flask\_compat.py", line 35, in reraise
    raise value
  File "c:\users\thanhpd8\appdata\local\programs\python\python37-32\lib\site-packages\flask\app.py", line 1813, in full_dispatch_request
    rv = self.dispatch_request()
  File "c:\users\thanhpd8\appdata\local\programs\python\python37-32\lib\site-packages\flask\app.py", line 1799, in dispatch_request
    return self.view_functions[rule.endpoint](**req.view_args)
  File "c:\users\thanhpd8\appdata\local\programs\python\python37-32\lib\site-packages\flask_login\utils.py", line 261, in decorated_view
    return func(*args, **kwargs)
  File "C:\Users\thanhpd8\Downloads\learning-python\learning-flask\microblog\app\routes.py", line 97, in edit_profile
    db.session.commit()
  File "c:\users\thanhpd8\appdata\local\programs\python\python37-32\lib\site-packages\sqlalchemy\orm\scoping.py", line 153, in do
    return getattr(self.registry(), name)(*args, **kwargs)
  File "c:\users\thanhpd8\appdata\local\programs\python\python37-32\lib\site-packages\sqlalchemy\orm\session.py", line 954, in commit
    self.transaction.commit()
  File "c:\users\thanhpd8\appdata\local\programs\python\python37-32\lib\site-packages\sqlalchemy\orm\session.py", line 467, in commit
    self._prepare_impl()
  File "c:\users\thanhpd8\appdata\local\programs\python\python37-32\lib\site-packages\sqlalchemy\orm\session.py", line 447, in _prepare_impl
    self.session.flush()
  File "c:\users\thanhpd8\appdata\local\programs\python\python37-32\lib\site-packages\sqlalchemy\orm\session.py", line 2313, in flush
    self._flush(objects)
  File "c:\users\thanhpd8\appdata\local\programs\python\python37-32\lib\site-packages\sqlalchemy\orm\session.py", line 2440, in _flush
    transaction.rollback(_capture_exception=True)
  File "c:\users\thanhpd8\appdata\local\programs\python\python37-32\lib\site-packages\sqlalchemy\util\langhelpers.py", line 66, in __exit__
    compat.reraise(exc_type, exc_value, exc_tb)
  File "c:\users\thanhpd8\appdata\local\programs\python\python37-32\lib\site-packages\sqlalchemy\util\compat.py", line 249, in reraise
    raise value
  File "c:\users\thanhpd8\appdata\local\programs\python\python37-32\lib\site-packages\sqlalchemy\orm\session.py", line 2404, in _flush
    flush_context.execute()
  File "c:\users\thanhpd8\appdata\local\programs\python\python37-32\lib\site-packages\sqlalchemy\orm\unitofwork.py", line 395, in execute
    rec.execute(self)
  File "c:\users\thanhpd8\appdata\local\programs\python\python37-32\lib\site-packages\sqlalchemy\orm\unitofwork.py", line 560, in execute
    uow
  File "c:\users\thanhpd8\appdata\local\programs\python\python37-32\lib\site-packages\sqlalchemy\orm\persistence.py", line 177, in save_obj
    mapper, table, update)
  File "c:\users\thanhpd8\appdata\local\programs\python\python37-32\lib\site-packages\sqlalchemy\orm\persistence.py", line 774, in _emit_update_statements
    execute(statement, multiparams)
  File "c:\users\thanhpd8\appdata\local\programs\python\python37-32\lib\site-packages\sqlalchemy\engine\base.py", line 948, in execute
    return meth(self, multiparams, params)
  File "c:\users\thanhpd8\appdata\local\programs\python\python37-32\lib\site-packages\sqlalchemy\sql\elements.py", line 269, in _execute_on_connection
    return connection._execute_clauseelement(self, multiparams, params)
  File "c:\users\thanhpd8\appdata\local\programs\python\python37-32\lib\site-packages\sqlalchemy\engine\base.py", line 1060, in _execute_clauseelement
    compiled_sql, distilled_params
  File "c:\users\thanhpd8\appdata\local\programs\python\python37-32\lib\site-packages\sqlalchemy\engine\base.py", line 1200, in _execute_context
    context)
  File "c:\users\thanhpd8\appdata\local\programs\python\python37-32\lib\site-packages\sqlalchemy\engine\base.py", line 1413, in _handle_dbapi_exception
    exc_info
  File "c:\users\thanhpd8\appdata\local\programs\python\python37-32\lib\site-packages\sqlalchemy\util\compat.py", line 265, in raise_from_cause
    reraise(type(exception), exception, tb=exc_tb, cause=cause)
  File "c:\users\thanhpd8\appdata\local\programs\python\python37-32\lib\site-packages\sqlalchemy\util\compat.py", line 248, in reraise
    raise value.with_traceback(tb)
  File "c:\users\thanhpd8\appdata\local\programs\python\python37-32\lib\site-packages\sqlalchemy\engine\base.py", line 1193, in _execute_context
    context)
  File "c:\users\thanhpd8\appdata\local\programs\python\python37-32\lib\site-packages\sqlalchemy\engine\default.py", line 509, in do_execute
    cursor.execute(statement, parameters)
sqlalchemy.exc.IntegrityError: (sqlite3.IntegrityError) UNIQUE constraint failed: user.username [SQL: 'UPDATE user SET username=?, about_me=? WHERE user.id = ?'] [parameters: ('thanh.phamduc', 'Well well well', 1)] (Background on this error at: http://sqlalche.me/e/gkpj)
2019-01-06 15:40:11,086 - INFO: Microblog startup [in C:\Users\thanhpd8\Downloads\learning-python\learning-flask\microblog\app\__init__.py:48]
2019-01-06 20:56:25,815 - INFO: Microblog startup [in C:\Users\thanhpd8\Downloads\learning-python\learning-flask\microblog\app\__init__.py:48]
